Workbook

Sheet Guide
A1: DATA ENTRY GUIDE — MULTIPLE GRAMMARS IN 1 FILE
A3: Each TAB (from 'Grammar 1' onwards) = 1 complete JSON object (title, language, isPublic, groups[], notes[], filterIds[]). To input multiple grammars at once, simply fill out multiple tabs, or right-click the 'Grammar 1' tab → Move or Copy → check 'Create a copy' to duplicate a new tab, and rename it as desired.
A5: STRUCTURE WITHIN EACH GRAMMAR TAB (Fixed rows — do not add or delete any row)
A6: Row 1 | B6: Banner (Not data)
A7: Row 5-7 | B7: ENERAL INFORMATION: title (B5) / language (B6) / isPublic (B7) → root object
A8: Row 11-40 | B8: COMPONENTS: GroupKey | Order | FormId (select) | FormId (value – use this column) | Keyword | Optional → each row is an element of groups[].components[], grouped by GroupKey Note: If a component contains a Keyword, the Form field is invalid. Therefore, leave the Form field empty whenever a keyword is specified for that component.
A9: Row 44-73 | B9: MEANINGS: GroupKey | MeaningOrder | Content | IsPublic → each row is an element of groups[].meanings[], grouped by GroupKey
A10: Row 77-116 | B10: EXAMPLES: GroupKey | MeaningOrder | Sentence | Translation | Note | IsPublic → each row is an element of examples[], attached to the correct meaning matching GroupKey + MeaningOrder
A11: Row 120-139 | B11: NOTES: GroupKey | Content | IsPublic → each row is an element of notes[]
A12: Row 143-162 | B12: FILTER IDS: FilterId (chọn) | FilterId (giá trị – dùng cột này) → combined into the filterIds[] array (ignoring blank rows)
A14: _Lookup' SHEET (Hidden)
A15: The place where the system writes key-value data retrieved from the DB BEFORE exporting the file to the user: - Columns A/B = (FormId, FormLabel) for the 'form' dropdown in all Grammar tabs. - Columns D/E = (FilterId, FilterLabel) for the 'filter' dropdown. All Grammar tabs share this single lookup list. See sample Java code below.
A17: QUY ƯỚC MÀU Ô
B18: Free input cell (typed manually)
B19: Dropdown selection cell (list loaded from the '_Lookup' sheet)
B20: Auto-calculated cell via formula — DO NOT edit manually; used to parse into JSON
A23: AI PROMPT — AUTOMATICALLY GENERATE GRAMMAR (Send this file along with this prompt to the AI)
A24: Fill in the prompt in the box below, then send this Excel file along with it to ask the AI to automatically populate the 'Grammar N' tabs according to the structure above.
A25: AI Prompt | B25: You are an expert Excel data entry assistant. YOUR TASK: Read the attached Excel template file (`grammar_entry_template.xlsx`), fill in all required data for the requested grammar points based on the strict rules below, and DIRECTLY OUTPUT THE COMPLETED EXCEL FILE (.xlsx) FOR DOWNLOAD. STRICTLY DO NOT provide code, explanations, or text-based tutorials—return only the final generated Excel file. ================================================== DATA ENTRY RULES FOR THE TEMPLATE: ================================================== 1. Tab Management: - The template contains fixed tabs: `Guide`, `_Lookup`, `Grammar 1`, `Grammar 2`, etc. - Each `Grammar X` tab corresponds to 1 grammar structure. Duplicate the `Grammar 1` tab to create enough tabs for all requested grammar points (`Grammar 1`, `Grammar 2`, ..., `Grammar N`). 2. General Information Section (Rows 3 - 7): - Row 5 (title): Enter the grammar structure title in Column B. - Row 6 (language): Enter [ ENTER SOURCE LANGUAGE CODE HERE, e.g., JA, EN, ZH, KO, etc. ] into Column B. - Row 7 (isPublic): Set to "TRUE". 3. PRESERVATION RULE FOR EXAMPLE / TEMPLATE ROWS (CRITICAL): - DO NOT touch, overwrite, or delete the first data row (the example row) in any table section (e.g., Row 11 for Components, Row 44 for Meanings, Row 77 for Examples, Row 120 for Notes, Row 143 for FilterIds). - ALWAYS start entering your actual data from the 2nd row of each section onwards: * Components: Start input from Row 12 * Meanings: Start input from Row 45 * Examples: Start input from Row 78 * Notes: Start input from Row 121 * FilterIds: Start input from Row 144 4. Components Section Rules (Starting from Row 12): - Each row represents a single component in sequential order (`Order` column starts at 0 for row 12, 1 for row 13, etc.). - A single row MUST contain EITHER a Form OR a Keyword. NEVER fill both Column C and Column E on the same row. - Column C (FormId / FormLabel): Check the `FormLabel` column (Column B) in the `_Lookup` tab. If the component matches one of these labels exactly, enter that exact label string into Column C, and leave Column E EMPTY. - Column E (Keyword): If the component is a particle, fixed grammar phrase, or anything NOT in the `_Lookup` tab, enter it directly into Column E, and leave Column C EMPTY. - PRIORITY RULE: If a single component could be construed as both a Form and a Keyword, or contains a fixed phrase/particle, PRIORITIZE KEYWORD (Fill Column E, leave Column C empty). - Column A (GroupKey): Always 0. - Column B (Order): Sequential integer index starting from 0 for each component. - Column F (Optional): Set to "TRUE". 5. FilterIds Section Rules (Starting from Row 144): - Check the `FilterLabel` column (Column E) in the `_Lookup` tab. - Enter the matching level / category string into Column A starting at Row 144 (`FilterId (chọn)`). 6. Content Section Rules (Meanings, Examples, Notes): - Target Language: Translate and fill Meanings, Example Translations, and Notes into [ ENTER TARGET TRANSLATION LANGUAGE HERE, e.g., English, Vietnamese, Spanish, etc. ]. - Meanings (Starting from Row 45): Column A = 0, Column B = MeaningOrder (0, 1...), Column C = Explanation, Column D = "TRUE". - Examples (Starting from Row 78): Column A = 0, Column B = Corresponding MeaningOrder, Column C = Example Sentence, Column D = Translation, Column F = "TRUE". - Notes (Starting from Row 121): Column A = 0, Column B = Usage Note, Column C = "TRUE". ================================================== [TARGET GRAMMAR DATA TO GENERATE] ================================================== - Target Translation Language: [ ENTER LANGUAGE, e.g., Vietnamese ] - Quantity: [ ENTER QUANTITY, e.g., 10 structures ] - Level / Category: [ ENTER LEVEL OR CATEGORY, e.g., N3, B2, HSK4, etc. ] - Specific Grammar List: [ PASTE LIST HERE OR WRITE: "Automatically select the most representative grammar points" ] GENERATE AND PROVIDE THE FINAL COMPLETED EXCEL FILE NOW!

Sheet _Lookup
A1: FormId | B1: FormLabel | D1: FilterId | E1: FilterLabel
A2: 3fa85f64-5717-4562-b3fc-2c963f66afa6 | B2: Danh từ (Noun) | D2: 3fa85f64-5717-4562-b3fc-2c963f66afa6 | E2: TOEIC
A3: 7c9e6679-7425-40de-944b-e07fc1f90ae7 | B3: Động từ (Verb) | D3: 9b2e1a3c-4d5f-4a6b-8c7d-1e2f3a4b5c6d | E3: IELTS

Sheet Grammar 1
A1: GRAMMAR TAB — 1 tab = 1 object JSON hoàn chỉnh (Grammar 1)
A3: 1. THÔNG TIN CHUNG → root: title / language / isPublic
A4: Field | B4: Value | C4: Ghi chú
A5: title | B5: Example: struct 'used to'
A6: language | B6: VI
A7: isPublic | B7: TRUE | C7: TRUE/FALSE
A9: 2. COMPONENTS → groups[].components[]
A10: GroupKey | B10: Order | C10: FormId (chọn) | D10: FormId (giá trị) | E10: Keyword | F10: Optional
A11: 0 | B11: 0 | C11: Danh từ (Noun) | E11: used to | F11: TRUE
D12: {=IFERROR(INDEX('_Lookup'!$A$2:$A$500,MATCH(C12,'_Lookup'!$B$2:$B$500,0)),"")}
D13: {=IFERROR(INDEX('_Lookup'!$A$2:$A$500,MATCH(C13,'_Lookup'!$B$2:$B$500,0)),"")}
D14: {=IFERROR(INDEX('_Lookup'!$A$2:$A$500,MATCH(C14,'_Lookup'!$B$2:$B$500,0)),"")}
D15: {=IFERROR(INDEX('_Lookup'!$A$2:$A$500,MATCH(C15,'_Lookup'!$B$2:$B$500,0)),"")}
D16: {=IFERROR(INDEX('_Lookup'!$A$2:$A$500,MATCH(C16,'_Lookup'!$B$2:$B$500,0)),"")}
D17: {=IFERROR(INDEX('_Lookup'!$A$2:$A$500,MATCH(C17,'_Lookup'!$B$2:$B$500,0)),"")}
D18: {=IFERROR(INDEX('_Lookup'!$A$2:$A$500,MATCH(C18,'_Lookup'!$B$2:$B$500,0)),"")}
D19: {=IFERROR(INDEX('_Lookup'!$A$2:$A$500,MATCH(C19,'_Lookup'!$B$2:$B$500,0)),"")}
D20: {=IFERROR(INDEX('_Lookup'!$A$2:$A$500,MATCH(C20,'_Lookup'!$B$2:$B$500,0)),"")}
D21: {=IFERROR(INDEX('_Lookup'!$A$2:$A$500,MATCH(C21,'_Lookup'!$B$2:$B$500,0)),"")}
D22: {=IFERROR(INDEX('_Lookup'!$A$2:$A$500,MATCH(C22,'_Lookup'!$B$2:$B$500,0)),"")}
D23: {=IFERROR(INDEX('_Lookup'!$A$2:$A$500,MATCH(C23,'_Lookup'!$B$2:$B$500,0)),"")}
... D40: {=IFERROR(INDEX('_Lookup'!$A$2:$A$500,MATCH(C40,'_Lookup'!$B$2:$B$500,0)),"")}
A42: 3. MEANINGS → groups[].meanings[]
A43: GroupKey | B43: MeaningOrder | C43: Content | D43: IsPublic
A44: 0 | B44: 0 | C44: Describes a past habit that no longer exists. | D44: TRUE
A75: 4. EXAMPLES → groups[].meanings[].examples[] (nối qua GroupKey + MeaningOrder)
A76: GroupKey | B76: MeaningOrder | C76: Sentence | D76: Translation | E76: Note | F76: IsPublic
A77: 0 | B77: 0 | C77: I used to play football every weekend. | D77: Tôi từng chơi bóng đá mỗi cuối tuần. | F77: TRUE
A118: 5. NOTES → notes[]
A119: GroupKey | B119: Content | C119: IsPublic
A120: 0 | B120: Not conjugated according to the subject; it is always followed by a verb infinitive (V-inf). | C120: TRUE
A141: 6. FILTER IDS → filterIds[]
A142: FilterId (chọn) | B142: FilterId (giá trị)
A143: TOEIC
B144: {=IFERROR(INDEX('_Lookup'!$D$2:$D$500,MATCH(A144,'_Lookup'!$E$2:$E$500,0)),"")}
B145: {=IFERROR(INDEX('_Lookup'!$D$2:$D$500,MATCH(A145,'_Lookup'!$E$2:$E$500,0)),"")}
B146: {=IFERROR(INDEX('_Lookup'!$D$2:$D$500,MATCH(A146,'_Lookup'!$E$2:$E$500,0)),"")}
B147: {=IFERROR(INDEX('_Lookup'!$D$2:$D$500,MATCH(A147,'_Lookup'!$E$2:$E$500,0)),"")}
B148: {=IFERROR(INDEX('_Lookup'!$D$2:$D$500,MATCH(A148,'_Lookup'!$E$2:$E$500,0)),"")}
B149: {=IFERROR(INDEX('_Lookup'!$D$2:$D$500,MATCH(A149,'_Lookup'!$E$2:$E$500,0)),"")}
...

Sheet Grammar 2
A1: GRAMMAR TAB — 1 tab = 1 object JSON hoàn chỉnh (Grammar 1)
A3: 1. THÔNG TIN CHUNG → root: title / language / isPublic
A4: Field | B4: Value | C4: Ghi chú
A5: title | B5: Example: struct 'used to'
A6: language | B6: VI
A7: isPublic | B7: TRUE | C7: TRUE/FALSE
A9: 2. COMPONENTS → groups[].components[]
A10: GroupKey | B10: Order | C10: FormId (chọn) | D10: FormId (giá trị) | E10: Keyword | F10: Optional
A11: 0 | B11: 0 | C11: Danh từ (Noun) | E11: used to | F11: TRUE
D12: {=IFERROR(INDEX('_Lookup'!$A$2:$A$500,MATCH(C12,'_Lookup'!$B$2:$B$500,0)),"")}
D13: {=IFERROR(INDEX('_Lookup'!$A$2:$A$500,MATCH(C13,'_Lookup'!$B$2:$B$500,0)),"")}
D14: {=IFERROR(INDEX('_Lookup'!$A$2:$A$500,MATCH(C14,'_Lookup'!$B$2:$B$500,0)),"")}
D15: {=IFERROR(INDEX('_Lookup'!$A$2:$A$500,MATCH(C15,'_Lookup'!$B$2:$B$500,0)),"")}
D16: {=IFERROR(INDEX('_Lookup'!$A$2:$A$500,MATCH(C16,'_Lookup'!$B$2:$B$500,0)),"")}
D17: {=IFERROR(INDEX('_Lookup'!$A$2:$A$500,MATCH(C17,'_Lookup'!$B$2:$B$500,0)),"")}
D18: {=IFERROR(INDEX('_Lookup'!$A$2:$A$500,MATCH(C18,'_Lookup'!$B$2:$B$500,0)),"")}
D19: {=IFERROR(INDEX('_Lookup'!$A$2:$A$500,MATCH(C19,'_Lookup'!$B$2:$B$500,0)),"")}
D20: {=IFERROR(INDEX('_Lookup'!$A$2:$A$500,MATCH(C20,'_Lookup'!$B$2:$B$500,0)),"")}
D21: {=IFERROR(INDEX('_Lookup'!$A$2:$A$500,MATCH(C21,'_Lookup'!$B$2:$B$500,0)),"")}
D22: {=IFERROR(INDEX('_Lookup'!$A$2:$A$500,MATCH(C22,'_Lookup'!$B$2:$B$500,0)),"")}
D23: {=IFERROR(INDEX('_Lookup'!$A$2:$A$500,MATCH(C23,'_Lookup'!$B$2:$B$500,0)),"")}
... D40: {=IFERROR(INDEX('_Lookup'!$A$2:$A$500,MATCH(C40,'_Lookup'!$B$2:$B$500,0)),"")}
A42: 3. MEANINGS → groups[].meanings[]
A43: GroupKey | B43: MeaningOrder | C43: Content | D43: IsPublic
A44: 0 | B44: 0 | C44: Describes a past habit that no longer exists. | D44: TRUE
A75: 4. EXAMPLES → groups[].meanings[].examples[] (nối qua GroupKey + MeaningOrder)
A76: GroupKey | B76: MeaningOrder | C76: Sentence | D76: Translation | E76: Note | F76: IsPublic
A77: 0 | B77: 0 | C77: I used to play football every weekend. | D77: Tôi từng chơi bóng đá mỗi cuối tuần. | F77: TRUE
A118: 5. NOTES → notes[]
A119: GroupKey | B119: Content | C119: IsPublic
A120: 0 | B120: Not conjugated according to the subject; it is always followed by a verb infinitive (V-inf). | C120: TRUE
A141: 6. FILTER IDS → filterIds[]
A142: FilterId (chọn) | B142: FilterId (giá trị)
A143: TOEIC
B144: {=IFERROR(INDEX('_Lookup'!$D$2:$D$500,MATCH(A144,'_Lookup'!$E$2:$E$500,0)),"")}
B145: {=IFERROR(INDEX('_Lookup'!$D$2:$D$500,MATCH(A145,'_Lookup'!$E$2:$E$500,0)),"")}
B146: {=IFERROR(INDEX('_Lookup'!$D$2:$D$500,MATCH(A146,'_Lookup'!$E$2:$E$500,0)),"")}
B147: {=IFERROR(INDEX('_Lookup'!$D$2:$D$500,MATCH(A147,'_Lookup'!$E$2:$E$500,0)),"")}
B148: {=IFERROR(INDEX('_Lookup'!$D$2:$D$500,MATCH(A148,'_Lookup'!$E$2:$E$500,0)),"")}
B149: {=IFERROR(INDEX('_Lookup'!$D$2:$D$500,MATCH(A149,'_Lookup'!$E$2:$E$500,0)),"")}
...

Sheet Grammar 3
A1: GRAMMAR TAB — 1 tab = 1 object JSON hoàn chỉnh (Grammar 1)
A3: 1. THÔNG TIN CHUNG → root: title / language / isPublic
A4: Field | B4: Value | C4: Ghi chú
A5: title | B5: Example: struct 'used to'
A6: language | B6: VI
A7: isPublic | B7: TRUE | C7: TRUE/FALSE
A9: 2. COMPONENTS → groups[].components[]
A10: GroupKey | B10: Order | C10: FormId (chọn) | D10: FormId (giá trị) | E10: Keyword | F10: Optional
A11: 0 | B11: 0 | C11: Danh từ (Noun) | E11: used to | F11: TRUE
D12: {=IFERROR(INDEX('_Lookup'!$A$2:$A$500,MATCH(C12,'_Lookup'!$B$2:$B$500,0)),"")}
D13: {=IFERROR(INDEX('_Lookup'!$A$2:$A$500,MATCH(C13,'_Lookup'!$B$2:$B$500,0)),"")}
D14: {=IFERROR(INDEX('_Lookup'!$A$2:$A$500,MATCH(C14,'_Lookup'!$B$2:$B$500,0)),"")}
D15: {=IFERROR(INDEX('_Lookup'!$A$2:$A$500,MATCH(C15,'_Lookup'!$B$2:$B$500,0)),"")}
D16: {=IFERROR(INDEX('_Lookup'!$A$2:$A$500,MATCH(C16,'_Lookup'!$B$2:$B$500,0)),"")}
D17: {=IFERROR(INDEX('_Lookup'!$A$2:$A$500,MATCH(C17,'_Lookup'!$B$2:$B$500,0)),"")}
D18: {=IFERROR(INDEX('_Lookup'!$A$2:$A$500,MATCH(C18,'_Lookup'!$B$2:$B$500,0)),"")}
D19: {=IFERROR(INDEX('_Lookup'!$A$2:$A$500,MATCH(C19,'_Lookup'!$B$2:$B$500,0)),"")}
D20: {=IFERROR(INDEX('_Lookup'!$A$2:$A$500,MATCH(C20,'_Lookup'!$B$2:$B$500,0)),"")}
D21: {=IFERROR(INDEX('_Lookup'!$A$2:$A$500,MATCH(C21,'_Lookup'!$B$2:$B$500,0)),"")}
D22: {=IFERROR(INDEX('_Lookup'!$A$2:$A$500,MATCH(C22,'_Lookup'!$B$2:$B$500,0)),"")}
D23: {=IFERROR(INDEX('_Lookup'!$A$2:$A$500,MATCH(C23,'_Lookup'!$B$2:$B$500,0)),"")}
... D40: {=IFERROR(INDEX('_Lookup'!$A$2:$A$500,MATCH(C40,'_Lookup'!$B$2:$B$500,0)),"")}
A42: 3. MEANINGS → groups[].meanings[]
A43: GroupKey | B43: MeaningOrder | C43: Content | D43: IsPublic
A44: 0 | B44: 0 | C44: Describes a past habit that no longer exists. | D44: TRUE
A75: 4. EXAMPLES → groups[].meanings[].examples[] (nối qua GroupKey + MeaningOrder)
A76: GroupKey | B76: MeaningOrder | C76: Sentence | D76: Translation | E76: Note | F76: IsPublic
A77: 0 | B77: 0 | C77: I used to play football every weekend. | D77: Tôi từng chơi bóng đá mỗi cuối tuần. | F77: TRUE
A118: 5. NOTES → notes[]
A119: GroupKey | B119: Content | C119: IsPublic
A120: 0 | B120: Not conjugated according to the subject; it is always followed by a verb infinitive (V-inf). | C120: TRUE
A141: 6. FILTER IDS → filterIds[]
A142: FilterId (chọn) | B142: FilterId (giá trị)
A143: TOEIC
B144: {=IFERROR(INDEX('_Lookup'!$D$2:$D$500,MATCH(A144,'_Lookup'!$E$2:$E$500,0)),"")}
B145: {=IFERROR(INDEX('_Lookup'!$D$2:$D$500,MATCH(A145,'_Lookup'!$E$2:$E$500,0)),"")}
B146: {=IFERROR(INDEX('_Lookup'!$D$2:$D$500,MATCH(A146,'_Lookup'!$E$2:$E$500,0)),"")}
B147: {=IFERROR(INDEX('_Lookup'!$D$2:$D$500,MATCH(A147,'_Lookup'!$E$2:$E$500,0)),"")}
B148: {=IFERROR(INDEX('_Lookup'!$D$2:$D$500,MATCH(A148,'_Lookup'!$E$2:$E$500,0)),"")}
B149: {=IFERROR(INDEX('_Lookup'!$D$2:$D$500,MATCH(A149,'_Lookup'!$E$2:$E$500,0)),"")}
...

Sheet Grammar 4
A1: GRAMMAR TAB — 1 tab = 1 object JSON hoàn chỉnh (Grammar 1)
A3: 1. THÔNG TIN CHUNG → root: title / language / isPublic
A4: Field | B4: Value | C4: Ghi chú
A5: title | B5: Example: struct 'used to'
A6: language | B6: VI
A7: isPublic | B7: TRUE | C7: TRUE/FALSE
A9: 2. COMPONENTS → groups[].components[]
A10: GroupKey | B10: Order | C10: FormId (chọn) | D10: FormId (giá trị) | E10: Keyword | F10: Optional
A11: 0 | B11: 0 | C11: Danh từ (Noun) | E11: used to | F11: TRUE
D12: {=IFERROR(INDEX('_Lookup'!$A$2:$A$500,MATCH(C12,'_Lookup'!$B$2:$B$500,0)),"")}
D13: {=IFERROR(INDEX('_Lookup'!$A$2:$A$500,MATCH(C13,'_Lookup'!$B$2:$B$500,0)),"")}
D14: {=IFERROR(INDEX('_Lookup'!$A$2:$A$500,MATCH(C14,'_Lookup'!$B$2:$B$500,0)),"")}
D15: {=IFERROR(INDEX('_Lookup'!$A$2:$A$500,MATCH(C15,'_Lookup'!$B$2:$B$500,0)),"")}
D16: {=IFERROR(INDEX('_Lookup'!$A$2:$A$500,MATCH(C16,'_Lookup'!$B$2:$B$500,0)),"")}
D17: {=IFERROR(INDEX('_Lookup'!$A$2:$A$500,MATCH(C17,'_Lookup'!$B$2:$B$500,0)),"")}
D18: {=IFERROR(INDEX('_Lookup'!$A$2:$A$500,MATCH(C18,'_Lookup'!$B$2:$B$500,0)),"")}
D19: {=IFERROR(INDEX('_Lookup'!$A$2:$A$500,MATCH(C19,'_Lookup'!$B$2:$B$500,0)),"")}
D20: {=IFERROR(INDEX('_Lookup'!$A$2:$A$500,MATCH(C20,'_Lookup'!$B$2:$B$500,0)),"")}
D21: {=IFERROR(INDEX('_Lookup'!$A$2:$A$500,MATCH(C21,'_Lookup'!$B$2:$B$500,0)),"")}
D22: {=IFERROR(INDEX('_Lookup'!$A$2:$A$500,MATCH(C22,'_Lookup'!$B$2:$B$500,0)),"")}
D23: {=IFERROR(INDEX('_Lookup'!$A$2:$A$500,MATCH(C23,'_Lookup'!$B$2:$B$500,0)),"")}
... D40: {=IFERROR(INDEX('_Lookup'!$A$2:$A$500,MATCH(C40,'_Lookup'!$B$2:$B$500,0)),"")}
A42: 3. MEANINGS → groups[].meanings[]
A43: GroupKey | B43: MeaningOrder | C43: Content | D43: IsPublic
A44: 0 | B44: 0 | C44: Describes a past habit that no longer exists. | D44: TRUE
A75: 4. EXAMPLES → groups[].meanings[].examples[] (nối qua GroupKey + MeaningOrder)
A76: GroupKey | B76: MeaningOrder | C76: Sentence | D76: Translation | E76: Note | F76: IsPublic
A77: 0 | B77: 0 | C77: I used to play football every weekend. | D77: Tôi từng chơi bóng đá mỗi cuối tuần. | F77: TRUE
A118: 5. NOTES → notes[]
A119: GroupKey | B119: Content | C119: IsPublic
A120: 0 | B120: Not conjugated according to the subject; it is always followed by a verb infinitive (V-inf). | C120: TRUE
A141: 6. FILTER IDS → filterIds[]
A142: FilterId (chọn) | B142: FilterId (giá trị)
A143: TOEIC
B144: {=IFERROR(INDEX('_Lookup'!$D$2:$D$500,MATCH(A144,'_Lookup'!$E$2:$E$500,0)),"")}
B145: {=IFERROR(INDEX('_Lookup'!$D$2:$D$500,MATCH(A145,'_Lookup'!$E$2:$E$500,0)),"")}
B146: {=IFERROR(INDEX('_Lookup'!$D$2:$D$500,MATCH(A146,'_Lookup'!$E$2:$E$500,0)),"")}
B147: {=IFERROR(INDEX('_Lookup'!$D$2:$D$500,MATCH(A147,'_Lookup'!$E$2:$E$500,0)),"")}
B148: {=IFERROR(INDEX('_Lookup'!$D$2:$D$500,MATCH(A148,'_Lookup'!$E$2:$E$500,0)),"")}
B149: {=IFERROR(INDEX('_Lookup'!$D$2:$D$500,MATCH(A149,'_Lookup'!$E$2:$E$500,0)),"")}
...
