Workbook

Sheet Guide
A1: DATA ENTRY GUIDE — MULTIPLE GRAMMARS IN 1 FILE
A3: Each TAB (from 'Grammar 1' onwards) = 1 complete JSON object (title, language, isPublic, groups[], notes[], filterIds[]). To input multiple grammars at once, simply fill out multiple tabs, or right-click the 'Grammar 1' tab → Move or Copy → check 'Create a copy' to duplicate a new tab, and rename it as desired.
A5: STRUCTURE WITHIN EACH GRAMMAR TAB (Fixed rows — do not add or delete any row)
A6: Row 1 | B6: Banner (Not data)
A7: Row 5-7 | B7: ENERAL INFORMATION: title (B5) / language (B6) / isPublic (B7) → root object
A8: Row 11-40 | B8: COMPONENTS: GroupKey | Order | FormId (select) | FormId (value – use this column) | Keyword | Optional → each row is an element of groups[].components[], grouped by GroupKey Note: If a component contains a Keyword, the Form field is invalid. Therefore, leave the Form field empty whenever a keyword is specified for that component.
A9: Row 44-73 | B9: MEANINGS: GroupKey | MeaningOrder | Content | IsPublic → each row is an element of groups[].meanings[], grouped by GroupKey
A10: Row 77-116 | B10: EXAMPLES: GroupKey | MeaningOrder | Sentence | Translation | Note | IsPublic → each row is an element of examples[], attached to the correct meaning matching GroupKey + MeaningOrder
A11: Row 120-139 | B11: NOTES: GroupKey | Content | IsPublic → each row is an element of notes[]
A12: Row 143-162 | B12: FILTER IDS: FilterId (chọn) | FilterId (giá trị – dùng cột này) → combined into the filterIds[] array (ignoring blank rows)
A13: NOTE | B13: Do not input in the example row, it will be skip when system read the file
A15: _Lookup' SHEET (Hidden)
A16: The place where the system writes key-value data retrieved from the DB BEFORE exporting the file to the user: - Columns A/B = (FormId, FormLabel) for the 'form' dropdown in all Grammar tabs. - Columns D/E = (FilterId, FilterLabel) for the 'filter' dropdown. All Grammar tabs share this single lookup list. See sample Java code below.
A18: QUY ƯỚC MÀU Ô
B19: Free input cell (typed manually)
B20: Dropdown selection cell (list loaded from the '_Lookup' sheet)
B21: Auto-calculated cell via formula — DO NOT edit manually; used to parse into JSON
A24: AI PROMPT — AUTOMATICALLY GENERATE GRAMMAR (Send this file along with this prompt to the AI)
A25: Fill in the prompt in the box below, then send this Excel file along with it to ask the AI to automatically populate the 'Grammar N' tabs according to the structure above.
A26: AI Prompt | B26: You are an expert Excel data entry assistant. YOUR TASK: Read the attached Excel template file (`grammar_entry_template.xlsx`), fill in all required data for the requested grammar points based on the strict rules below, and DIRECTLY OUTPUT THE COMPLETED EXCEL FILE (.xlsx) FOR DOWNLOAD. STRICTLY DO NOT provide code, explanations, or text-based tutorials—return only the final generated Excel file. ================================================== DATA ENTRY RULES FOR THE TEMPLATE: ================================================== 1. Tab Management: - The template contains fixed tabs: `Guide`, `_Lookup`, `Grammar 1`, `Grammar 2`, etc. - Each `Grammar X` tab corresponds to 1 grammar structure. Duplicate the `Grammar 1` tab to create enough tabs for all requested grammar points (`Grammar 1`, `Grammar 2`, ..., `Grammar N`). 2. General Information Section (Rows 3 - 7): - Row 5 (title): Enter the grammar structure title in Column B. - Row 6 (language): Enter [ ENTER SOURCE LANGUAGE CODE HERE, e.g., JA, EN, ZH, KO, etc. ] into Column B. - Row 7 (isPublic): Set to "TRUE". 3. PRESERVATION RULE FOR EXAMPLE / TEMPLATE ROWS (CRITICAL): - DO NOT touch, overwrite, or delete the first data row (the example row) in any table section (e.g., Row 11 for Components, Row 44 for Meanings, Row 77 for Examples, Row 120 for Notes, Row 143 for FilterIds). - ALWAYS start entering your actual data from the 2nd row of each section onwards: * Components: Start input from Row 12 * Meanings: Start input from Row 45 * Examples: Start input from Row 78 * Notes: Start input from Row 121 * FilterIds: Start input from Row 144 4. Components Section Rules (Starting from Row 12): - Each row represents a single component in sequential order (`Order` column starts at 0 for row 12, 1 for row 13, etc.). - A single row MUST contain EITHER a Form OR a Keyword. NEVER fill both Column C and Column E on the same row. - Column C (FormId / FormLabel): Check the `FormLabel` column (Column B) in the `_Lookup` tab. If the component matches one of these labels exactly, enter that exact label string into Column C, and leave Column E EMPTY. - Column E (Keyword): If the component is a particle, fixed grammar phrase, or anything NOT in the `_Lookup` tab, enter it directly into Column E, and leave Column C EMPTY. - PRIORITY RULE: If a single component could be construed as both a Form and a Keyword, or contains a fixed phrase/particle, PRIORITIZE KEYWORD (Fill Column E, leave Column C empty). - Column A (GroupKey): Always 0. - Column B (Order): Sequential integer index starting from 0 for each component. - Column F (Optional): Set to "TRUE". 5. FilterIds Section Rules (Starting from Row 144): - Check the `FilterLabel` column (Column E) in the `_Lookup` tab. - Enter the matching level / category string into Column A starting at Row 144 (`FilterId (chọn)`). 6. Content Section Rules (Meanings, Examples, Notes): - Target Language: Translate and fill Meanings, Example Translations, and Notes into [ ENTER TARGET TRANSLATION LANGUAGE HERE, e.g., English, Vietnamese, Spanish, etc. ]. - Meanings (Starting from Row 45): Column A = 0, Column B = MeaningOrder (0, 1...), Column C = Explanation, Column D = "TRUE". - Examples (Starting from Row 78): Column A = 0, Column B = Corresponding MeaningOrder, Column C = Example Sentence, Column D = Translation, Column F = "TRUE". - Notes (Starting from Row 121): Column A = 0, Column B = Usage Note, Column C = "TRUE". ================================================== [TARGET GRAMMAR DATA TO GENERATE] ================================================== - Grammar Language Code: [ ENTER CODE, e.g., JA ] - Target Translation Language: [ ENTER LANGUAGE, e.g., Vietnamese ] - Quantity: [ ENTER QUANTITY, e.g., 10 structures ] - Level / Category: [ ENTER LEVEL OR CATEGORY, e.g., N3, B2, HSK4, etc. ] - Specific Grammar List: [ PASTE LIST HERE OR WRITE: "Automatically select the most representative grammar points" ] GENERATE AND PROVIDE THE FINAL COMPLETED EXCEL FILE NOW!

Sheet _Lookup
A1: FormId | B1: FormLabel | D1: FilterId | E1: FilterLabel
A2: 170047db-fefd-467b-99c3-c939bf6491b9 | B2: N | D2: 1446ae3e-7f7c-4520-ac0a-f648b12bf129 | E2: N5
A3: 38ed8029-5089-4a4f-a746-5bddaa71994e | B3: V-short | D3: a29446b7-38d0-4466-8bf5-22912940780c | E3: N4
A4: 6c0fe80c-b002-4fd0-8724-5cd636218242 | B4: V-て | D4: c3a0a730-9fcd-48fa-9c1a-d134ed523b41 | E4: N3
A5: 8fd3ee84-10ca-4364-a546-4273a8bccbb9 | B5: V-ない | D5: f4b41b8b-b7b8-4cc9-a94b-04043cbd6be6 | E5: N2
A6: 5c955868-7ebd-4365-ae99-9a4d6efc3fd7 | B6: JA | D6: a6bddc20-21c2-4c87-9e6f-94b4d61db703 | E6: N1

Sheet Grammar 1
A1: GRAMMAR TAB — 1 tab = 1 object JSON hoàn chỉnh (Grammar 1)
A3: 1. THÔNG TIN CHUNG → root: title / language / isPublic
A4: Field | B4: Value | C4: Ghi chú
A5: title | B5: ~てはいけない (te wa ikenai)
A6: language | B6: JA
A7: isPublic | B7: TRUE | C7: TRUE/FALSE
A9: 2. COMPONENTS → groups[].components[]
A10: GroupKey | B10: Order | C10: FormId (chọn) | D10: FormId (giá trị) | E10: Keyword | F10: Optional
A11: 0 | B11: 0 | C11: Động từ (Verb) | E11: used to | F11: TRUE
A12: 0 | B12: 0 | C12: V-て | D12: {=IFERROR(INDEX(_Lookup!$A$2:$A$500,MATCH(C12,_Lookup!$B$2:$B$500,0)),"")} | F12: TRUE
A13: 0 | B13: 1 | D13: {=IFERROR(INDEX(_Lookup!$A$2:$A$500,MATCH(C13,_Lookup!$B$2:$B$500,0)),"")} | E13: はいけない | F13: TRUE
D14: {=IFERROR(INDEX(_Lookup!$A$2:$A$500,MATCH(C14,_Lookup!$B$2:$B$500,0)),"")}
D15: {=IFERROR(INDEX(_Lookup!$A$2:$A$500,MATCH(C15,_Lookup!$B$2:$B$500,0)),"")}
D16: {=IFERROR(INDEX(_Lookup!$A$2:$A$500,MATCH(C16,_Lookup!$B$2:$B$500,0)),"")}
D17: {=IFERROR(INDEX(_Lookup!$A$2:$A$500,MATCH(C17,_Lookup!$B$2:$B$500,0)),"")}
D18: {=IFERROR(INDEX(_Lookup!$A$2:$A$500,MATCH(C18,_Lookup!$B$2:$B$500,0)),"")}
D19: {=IFERROR(INDEX(_Lookup!$A$2:$A$500,MATCH(C19,_Lookup!$B$2:$B$500,0)),"")}
D20: {=IFERROR(INDEX(_Lookup!$A$2:$A$500,MATCH(C20,_Lookup!$B$2:$B$500,0)),"")}
D21: {=IFERROR(INDEX(_Lookup!$A$2:$A$500,MATCH(C21,_Lookup!$B$2:$B$500,0)),"")}
D22: {=IFERROR(INDEX(_Lookup!$A$2:$A$500,MATCH(C22,_Lookup!$B$2:$B$500,0)),"")}
D23: {=IFERROR(INDEX(_Lookup!$A$2:$A$500,MATCH(C23,_Lookup!$B$2:$B$500,0)),"")}
D24: {=IFERROR(INDEX(_Lookup!$A$2:$A$500,MATCH(C24,_Lookup!$B$2:$B$500,0)),"")}
D25: {=IFERROR(INDEX(_Lookup!$A$2:$A$500,MATCH(C25,_Lookup!$B$2:$B$500,0)),"")}
... D40: {=IFERROR(INDEX(_Lookup!$A$2:$A$500,MATCH(C40,_Lookup!$B$2:$B$500,0)),"")}
A42: 3. MEANINGS → groups[].meanings[]
A43: GroupKey | B43: MeaningOrder | C43: Content | D43: IsPublic
A44: 0 | B44: 0 | C44: Describes a past habit that no longer exists. | D44: TRUE
A45: 0 | B45: 0 | C45: Must not do; expressing prohibition. | D45: TRUE
A75: 4. EXAMPLES → groups[].meanings[].examples[] (nối qua GroupKey + MeaningOrder)
A76: GroupKey | B76: MeaningOrder | C76: Sentence | D76: Translation | E76: Note | F76: IsPublic
A77: 0 | B77: 0 | C77: I used to play football every weekend. | D77: Tôi từng chơi bóng đá mỗi cuối tuần. | F77: TRUE
A78: 0 | B78: 0 | C78: ここで写真を撮ってはいけません。 | D78: You must not take photos here. | F78: TRUE
A79: 0 | B79: 0 | C79: 図書館でおしゃべりをしてはいけません。 | D79: You must not talk in the library. | F79: TRUE
A118: 5. NOTES → notes[]
A119: GroupKey | B119: Content | C119: IsPublic
A120: 0 | B120: Not conjugated according to the subject; it is always followed by a verb infinitive (V-inf). | C120: TRUE
A121: 0 | B121: Used to state strong prohibitions or rules. | C121: TRUE
A141: 6. FILTER IDS → filterIds[]
A142: FilterId (chọn) | B142: FilterId (giá trị)
A143: TOEIC
...

Sheet Grammar 2
A1: GRAMMAR TAB — 1 tab = 1 object JSON hoàn chỉnh (Grammar 1)
A3: 1. THÔNG TIN CHUNG → root: title / language / isPublic
A4: Field | B4: Value | C4: Ghi chú
A5: title | B5: ~ことにする (koto ni suru)
A6: language | B6: JA
A7: isPublic | B7: TRUE | C7: TRUE/FALSE
A9: 2. COMPONENTS → groups[].components[]
A10: GroupKey | B10: Order | C10: FormId (chọn) | D10: FormId (giá trị) | E10: Keyword | F10: Optional
A11: 0 | B11: 0 | C11: Danh từ (Noun) | E11: used to | F11: TRUE
A12: 0 | B12: 0 | C12: V-short | D12: {=IFERROR(INDEX(_Lookup!$A$2:$A$500,MATCH(C12,_Lookup!$B$2:$B$500,0)),"")} | F12: TRUE
A13: 0 | B13: 1 | D13: {=IFERROR(INDEX(_Lookup!$A$2:$A$500,MATCH(C13,_Lookup!$B$2:$B$500,0)),"")} | E13: ことにする | F13: TRUE
D14: {=IFERROR(INDEX(_Lookup!$A$2:$A$500,MATCH(C14,_Lookup!$B$2:$B$500,0)),"")}
D15: {=IFERROR(INDEX(_Lookup!$A$2:$A$500,MATCH(C15,_Lookup!$B$2:$B$500,0)),"")}
D16: {=IFERROR(INDEX(_Lookup!$A$2:$A$500,MATCH(C16,_Lookup!$B$2:$B$500,0)),"")}
D17: {=IFERROR(INDEX(_Lookup!$A$2:$A$500,MATCH(C17,_Lookup!$B$2:$B$500,0)),"")}
D18: {=IFERROR(INDEX(_Lookup!$A$2:$A$500,MATCH(C18,_Lookup!$B$2:$B$500,0)),"")}
D19: {=IFERROR(INDEX(_Lookup!$A$2:$A$500,MATCH(C19,_Lookup!$B$2:$B$500,0)),"")}
D20: {=IFERROR(INDEX(_Lookup!$A$2:$A$500,MATCH(C20,_Lookup!$B$2:$B$500,0)),"")}
D21: {=IFERROR(INDEX(_Lookup!$A$2:$A$500,MATCH(C21,_Lookup!$B$2:$B$500,0)),"")}
D22: {=IFERROR(INDEX(_Lookup!$A$2:$A$500,MATCH(C22,_Lookup!$B$2:$B$500,0)),"")}
D23: {=IFERROR(INDEX(_Lookup!$A$2:$A$500,MATCH(C23,_Lookup!$B$2:$B$500,0)),"")}
D24: {=IFERROR(INDEX(_Lookup!$A$2:$A$500,MATCH(C24,_Lookup!$B$2:$B$500,0)),"")}
D25: {=IFERROR(INDEX(_Lookup!$A$2:$A$500,MATCH(C25,_Lookup!$B$2:$B$500,0)),"")}
... D40: {=IFERROR(INDEX(_Lookup!$A$2:$A$500,MATCH(C40,_Lookup!$B$2:$B$500,0)),"")}
A42: 3. MEANINGS → groups[].meanings[]
A43: GroupKey | B43: MeaningOrder | C43: Content | D43: IsPublic
A44: 0 | B44: 0 | C44: Describes a past habit that no longer exists. | D44: TRUE
A45: 0 | B45: 0 | C45: Decide to do something (expresses a personal decision or choice). | D45: TRUE
A75: 4. EXAMPLES → groups[].meanings[].examples[] (nối qua GroupKey + MeaningOrder)
A76: GroupKey | B76: MeaningOrder | C76: Sentence | D76: Translation | E76: Note | F76: IsPublic
A77: 0 | B77: 0 | C77: I used to play football every weekend. | D77: Tôi từng chơi bóng đá mỗi cuối tuần. | F77: TRUE
A78: 0 | B78: 0 | C78: 毎日走ることにしました。 | D78: I decided to run every day. | F78: TRUE
A79: 0 | B79: 0 | C79: 甘いものを食べないことにしています。 | D79: I make it a rule not to eat sweets. | F79: TRUE
A118: 5. NOTES → notes[]
A119: GroupKey | B119: Content | C119: IsPublic
A120: 0 | B120: Not conjugated according to the subject; it is always followed by a verb infinitive (V-inf). | C120: TRUE
A121: 0 | B121: ~ことにしている indicates a personal habit or ongoing rule self-imposed by the speaker. | C121: TRUE
A141: 6. FILTER IDS → filterIds[]
A142: FilterId (chọn) | B142: FilterId (giá trị)
A143: TOEIC
...

Sheet Grammar 3
A1: GRAMMAR TAB — 1 tab = 1 object JSON hoàn chỉnh (Grammar 1)
A3: 1. THÔNG TIN CHUNG → root: title / language / isPublic
A4: Field | B4: Value | C4: Ghi chú
A5: title | B5: ~ようにする (you ni suru)
A6: language | B6: JA
A7: isPublic | B7: TRUE | C7: TRUE/FALSE
A9: 2. COMPONENTS → groups[].components[]
A10: GroupKey | B10: Order | C10: FormId (chọn) | D10: FormId (giá trị) | E10: Keyword | F10: Optional
A11: 0 | B11: 0 | C11: Danh từ (Noun) | E11: used to | F11: TRUE
A12: 0 | B12: 0 | C12: V-short | D12: {=IFERROR(INDEX(_Lookup!$A$2:$A$500,MATCH(C12,_Lookup!$B$2:$B$500,0)),"")} | F12: TRUE
A13: 0 | B13: 1 | D13: {=IFERROR(INDEX(_Lookup!$A$2:$A$500,MATCH(C13,_Lookup!$B$2:$B$500,0)),"")} | E13: ようにする | F13: TRUE
D14: {=IFERROR(INDEX(_Lookup!$A$2:$A$500,MATCH(C14,_Lookup!$B$2:$B$500,0)),"")}
D15: {=IFERROR(INDEX(_Lookup!$A$2:$A$500,MATCH(C15,_Lookup!$B$2:$B$500,0)),"")}
D16: {=IFERROR(INDEX(_Lookup!$A$2:$A$500,MATCH(C16,_Lookup!$B$2:$B$500,0)),"")}
D17: {=IFERROR(INDEX(_Lookup!$A$2:$A$500,MATCH(C17,_Lookup!$B$2:$B$500,0)),"")}
D18: {=IFERROR(INDEX(_Lookup!$A$2:$A$500,MATCH(C18,_Lookup!$B$2:$B$500,0)),"")}
D19: {=IFERROR(INDEX(_Lookup!$A$2:$A$500,MATCH(C19,_Lookup!$B$2:$B$500,0)),"")}
D20: {=IFERROR(INDEX(_Lookup!$A$2:$A$500,MATCH(C20,_Lookup!$B$2:$B$500,0)),"")}
D21: {=IFERROR(INDEX(_Lookup!$A$2:$A$500,MATCH(C21,_Lookup!$B$2:$B$500,0)),"")}
D22: {=IFERROR(INDEX(_Lookup!$A$2:$A$500,MATCH(C22,_Lookup!$B$2:$B$500,0)),"")}
D23: {=IFERROR(INDEX(_Lookup!$A$2:$A$500,MATCH(C23,_Lookup!$B$2:$B$500,0)),"")}
D24: {=IFERROR(INDEX(_Lookup!$A$2:$A$500,MATCH(C24,_Lookup!$B$2:$B$500,0)),"")}
D25: {=IFERROR(INDEX(_Lookup!$A$2:$A$500,MATCH(C25,_Lookup!$B$2:$B$500,0)),"")}
... D40: {=IFERROR(INDEX(_Lookup!$A$2:$A$500,MATCH(C40,_Lookup!$B$2:$B$500,0)),"")}
A42: 3. MEANINGS → groups[].meanings[]
A43: GroupKey | B43: MeaningOrder | C43: Content | D43: IsPublic
A44: 0 | B44: 0 | C44: Describes a past habit that no longer exists. | D44: TRUE
A45: 0 | B45: 0 | C45: Try to do / make sure to do something as an ongoing effort. | D45: TRUE
A75: 4. EXAMPLES → groups[].meanings[].examples[] (nối qua GroupKey + MeaningOrder)
A76: GroupKey | B76: MeaningOrder | C76: Sentence | D76: Translation | E76: Note | F76: IsPublic
A77: 0 | B77: 0 | C77: I used to play football every weekend. | D77: Tôi từng chơi bóng đá mỗi cuối tuần. | F77: TRUE
A78: 0 | B78: 0 | C78: 野菜をたくさん食べるようにしています。 | D78: I try to eat a lot of vegetables. | F78: TRUE
A79: 0 | B79: 0 | C79: 遅刻しないようにしてください。 | D79: Please try not to be late. | F79: TRUE
A118: 5. NOTES → notes[]
A119: GroupKey | B119: Content | C119: IsPublic
A120: 0 | B120: Not conjugated according to the subject; it is always followed by a verb infinitive (V-inf). | C120: TRUE
A121: 0 | B121: Focuses on continuous effort or conscious habit formation. | C121: TRUE
A141: 6. FILTER IDS → filterIds[]
A142: FilterId (chọn) | B142: FilterId (giá trị)
A143: TOEIC
...

Sheet Grammar 4
A1: GRAMMAR TAB — 1 tab = 1 object JSON hoàn chỉnh (Grammar 1)
A3: 1. THÔNG TIN CHUNG → root: title / language / isPublic
A4: Field | B4: Value | C4: Ghi chú
A5: title | B5: ~ことにしている (koto ni shite iru)
A6: language | B6: JA
A7: isPublic | B7: TRUE | C7: TRUE/FALSE
A9: 2. COMPONENTS → groups[].components[]
A10: GroupKey | B10: Order | C10: FormId (chọn) | D10: FormId (giá trị) | E10: Keyword | F10: Optional
A11: 0 | B11: 0 | C11: Danh từ (Noun) | E11: used to | F11: TRUE
A12: 0 | B12: 0 | C12: V-short | D12: {=IFERROR(INDEX(_Lookup!$A$2:$A$500,MATCH(C12,_Lookup!$B$2:$B$500,0)),"")} | F12: TRUE
A13: 0 | B13: 1 | D13: {=IFERROR(INDEX(_Lookup!$A$2:$A$500,MATCH(C13,_Lookup!$B$2:$B$500,0)),"")} | E13: ことにしている | F13: TRUE
D14: {=IFERROR(INDEX(_Lookup!$A$2:$A$500,MATCH(C14,_Lookup!$B$2:$B$500,0)),"")}
D15: {=IFERROR(INDEX(_Lookup!$A$2:$A$500,MATCH(C15,_Lookup!$B$2:$B$500,0)),"")}
D16: {=IFERROR(INDEX(_Lookup!$A$2:$A$500,MATCH(C16,_Lookup!$B$2:$B$500,0)),"")}
D17: {=IFERROR(INDEX(_Lookup!$A$2:$A$500,MATCH(C17,_Lookup!$B$2:$B$500,0)),"")}
D18: {=IFERROR(INDEX(_Lookup!$A$2:$A$500,MATCH(C18,_Lookup!$B$2:$B$500,0)),"")}
D19: {=IFERROR(INDEX(_Lookup!$A$2:$A$500,MATCH(C19,_Lookup!$B$2:$B$500,0)),"")}
D20: {=IFERROR(INDEX(_Lookup!$A$2:$A$500,MATCH(C20,_Lookup!$B$2:$B$500,0)),"")}
D21: {=IFERROR(INDEX(_Lookup!$A$2:$A$500,MATCH(C21,_Lookup!$B$2:$B$500,0)),"")}
D22: {=IFERROR(INDEX(_Lookup!$A$2:$A$500,MATCH(C22,_Lookup!$B$2:$B$500,0)),"")}
D23: {=IFERROR(INDEX(_Lookup!$A$2:$A$500,MATCH(C23,_Lookup!$B$2:$B$500,0)),"")}
D24: {=IFERROR(INDEX(_Lookup!$A$2:$A$500,MATCH(C24,_Lookup!$B$2:$B$500,0)),"")}
D25: {=IFERROR(INDEX(_Lookup!$A$2:$A$500,MATCH(C25,_Lookup!$B$2:$B$500,0)),"")}
... D40: {=IFERROR(INDEX(_Lookup!$A$2:$A$500,MATCH(C40,_Lookup!$B$2:$B$500,0)),"")}
A42: 3. MEANINGS → groups[].meanings[]
A43: GroupKey | B43: MeaningOrder | C43: Content | D43: IsPublic
A44: 0 | B44: 0 | C44: Describes a past habit that no longer exists. | D44: TRUE
A45: 0 | B45: 0 | C45: Make it a rule to / make a practice of doing something. | D45: TRUE
A75: 4. EXAMPLES → groups[].meanings[].examples[] (nối qua GroupKey + MeaningOrder)
A76: GroupKey | B76: MeaningOrder | C76: Sentence | D76: Translation | E76: Note | F76: IsPublic
A77: 0 | B77: 0 | C77: I used to play football every weekend. | D77: Tôi từng chơi bóng đá mỗi cuối tuần. | F77: TRUE
A78: 0 | B78: 0 | C78: 毎朝６時に起きることにしています。 | D78: I make it a habit to wake up at 6 AM every morning. | F78: TRUE
A79: 0 | B79: 0 | C79: 夜遅くには何も食べないことにしています。 | D79: I make it a rule not to eat anything late at night. | F79: TRUE
A118: 5. NOTES → notes[]
A119: GroupKey | B119: Content | C119: IsPublic
A120: 0 | B120: Not conjugated according to the subject; it is always followed by a verb infinitive (V-inf). | C120: TRUE
A121: 0 | B121: Represents a routine or habit based on personal determination. | C121: TRUE
A141: 6. FILTER IDS → filterIds[]
A142: FilterId (chọn) | B142: FilterId (giá trị)
A143: TOEIC
...

Sheet Grammar 5
A1: GRAMMAR TAB — 1 tab = 1 object JSON hoàn chỉnh (Grammar 1)
A3: 1. THÔNG TIN CHUNG → root: title / language / isPublic
A4: Field | B4: Value | C4: Ghi chú
A5: title | B5: ~わけにはいかない (wake ni wa ikanai)
A6: language | B6: JA
A7: isPublic | B7: TRUE | C7: TRUE/FALSE
A9: 2. COMPONENTS → groups[].components[]
A10: GroupKey | B10: Order | C10: FormId (chọn) | D10: FormId (giá trị) | E10: Keyword | F10: Optional
A11: 0 | B11: 0 | C11: Động từ (Verb) | E11: used to | F11: TRUE
A12: 0 | B12: 0 | C12: V-short | D12: {=IFERROR(INDEX(_Lookup!$A$2:$A$500,MATCH(C12,_Lookup!$B$2:$B$500,0)),"")} | F12: TRUE
A13: 0 | B13: 1 | D13: {=IFERROR(INDEX(_Lookup!$A$2:$A$500,MATCH(C13,_Lookup!$B$2:$B$500,0)),"")} | E13: わけにはいかない | F13: TRUE
D14: {=IFERROR(INDEX(_Lookup!$A$2:$A$500,MATCH(C14,_Lookup!$B$2:$B$500,0)),"")}
D15: {=IFERROR(INDEX(_Lookup!$A$2:$A$500,MATCH(C15,_Lookup!$B$2:$B$500,0)),"")}
D16: {=IFERROR(INDEX(_Lookup!$A$2:$A$500,MATCH(C16,_Lookup!$B$2:$B$500,0)),"")}
D17: {=IFERROR(INDEX(_Lookup!$A$2:$A$500,MATCH(C17,_Lookup!$B$2:$B$500,0)),"")}
D18: {=IFERROR(INDEX(_Lookup!$A$2:$A$500,MATCH(C18,_Lookup!$B$2:$B$500,0)),"")}
D19: {=IFERROR(INDEX(_Lookup!$A$2:$A$500,MATCH(C19,_Lookup!$B$2:$B$500,0)),"")}
D20: {=IFERROR(INDEX(_Lookup!$A$2:$A$500,MATCH(C20,_Lookup!$B$2:$B$500,0)),"")}
D21: {=IFERROR(INDEX(_Lookup!$A$2:$A$500,MATCH(C21,_Lookup!$B$2:$B$500,0)),"")}
D22: {=IFERROR(INDEX(_Lookup!$A$2:$A$500,MATCH(C22,_Lookup!$B$2:$B$500,0)),"")}
D23: {=IFERROR(INDEX(_Lookup!$A$2:$A$500,MATCH(C23,_Lookup!$B$2:$B$500,0)),"")}
D24: {=IFERROR(INDEX(_Lookup!$A$2:$A$500,MATCH(C24,_Lookup!$B$2:$B$500,0)),"")}
D25: {=IFERROR(INDEX(_Lookup!$A$2:$A$500,MATCH(C25,_Lookup!$B$2:$B$500,0)),"")}
... D40: {=IFERROR(INDEX(_Lookup!$A$2:$A$500,MATCH(C40,_Lookup!$B$2:$B$500,0)),"")}
A42: 3. MEANINGS → groups[].meanings[]
A43: GroupKey | B43: MeaningOrder | C43: Content | D43: IsPublic
A44: 0 | B44: 0 | C44: Describes a past habit that no longer exists. | D44: TRUE
A45: 0 | B45: 0 | C45: Cannot afford to / impossible to do due to social, moral, or situational obligations. | D45: TRUE
A75: 4. EXAMPLES → groups[].meanings[].examples[] (nối qua GroupKey + MeaningOrder)
A76: GroupKey | B76: MeaningOrder | C76: Sentence | D76: Translation | E76: Note | F76: IsPublic
A77: 0 | B77: 0 | C77: I used to play football every weekend. | D77: Tôi từng chơi bóng đá mỗi cuối tuần. | F77: TRUE
A78: 0 | B78: 0 | C78: 大事な会議があるから、休むわけにはいかない。 | D78: Because there is an important meeting, I cannot afford to take time off. | F78: TRUE
A79: 0 | B79: 0 | C79: 約束したから、断るわけにはいかない。 | D79: Since I promised, I cannot refuse. | F79: TRUE
A118: 5. NOTES → notes[]
A119: GroupKey | B119: Content | C119: IsPublic
A120: 0 | B120: Not conjugated according to the subject; it is always followed by a verb infinitive (V-inf). | C120: TRUE
A121: 0 | B121: Expresses inability to do something not because of physical impossibility, but due to psychological, moral, or social constraints. | C121: TRUE
A141: 6. FILTER IDS → filterIds[]
A142: FilterId (chọn) | B142: FilterId (giá trị)
A143: TOEIC
...

Sheet Grammar 6
A1: GRAMMAR TAB — 1 tab = 1 object JSON hoàn chỉnh (Grammar 1)
A3: 1. THÔNG TIN CHUNG → root: title / language / isPublic
A4: Field | B4: Value | C4: Ghi chú
A5: title | B5: ~おそれがある (osore ga aru)
A6: language | B6: JA
A7: isPublic | B7: TRUE | C7: TRUE/FALSE
A9: 2. COMPONENTS → groups[].components[]
A10: GroupKey | B10: Order | C10: FormId (chọn) | D10: FormId (giá trị) | E10: Keyword | F10: Optional
A11: 0 | B11: 0 | C11: Động từ (Verb) | E11: used to | F11: TRUE
A12: 0 | B12: 0 | C12: V-short | D12: {=IFERROR(INDEX(_Lookup!$A$2:$A$500,MATCH(C12,_Lookup!$B$2:$B$500,0)),"")} | F12: TRUE
A13: 0 | B13: 1 | D13: {=IFERROR(INDEX(_Lookup!$A$2:$A$500,MATCH(C13,_Lookup!$B$2:$B$500,0)),"")} | E13: おそれがある | F13: TRUE
D14: {=IFERROR(INDEX(_Lookup!$A$2:$A$500,MATCH(C14,_Lookup!$B$2:$B$500,0)),"")}
D15: {=IFERROR(INDEX(_Lookup!$A$2:$A$500,MATCH(C15,_Lookup!$B$2:$B$500,0)),"")}
D16: {=IFERROR(INDEX(_Lookup!$A$2:$A$500,MATCH(C16,_Lookup!$B$2:$B$500,0)),"")}
D17: {=IFERROR(INDEX(_Lookup!$A$2:$A$500,MATCH(C17,_Lookup!$B$2:$B$500,0)),"")}
D18: {=IFERROR(INDEX(_Lookup!$A$2:$A$500,MATCH(C18,_Lookup!$B$2:$B$500,0)),"")}
D19: {=IFERROR(INDEX(_Lookup!$A$2:$A$500,MATCH(C19,_Lookup!$B$2:$B$500,0)),"")}
D20: {=IFERROR(INDEX(_Lookup!$A$2:$A$500,MATCH(C20,_Lookup!$B$2:$B$500,0)),"")}
D21: {=IFERROR(INDEX(_Lookup!$A$2:$A$500,MATCH(C21,_Lookup!$B$2:$B$500,0)),"")}
D22: {=IFERROR(INDEX(_Lookup!$A$2:$A$500,MATCH(C22,_Lookup!$B$2:$B$500,0)),"")}
D23: {=IFERROR(INDEX(_Lookup!$A$2:$A$500,MATCH(C23,_Lookup!$B$2:$B$500,0)),"")}
D24: {=IFERROR(INDEX(_Lookup!$A$2:$A$500,MATCH(C24,_Lookup!$B$2:$B$500,0)),"")}
D25: {=IFERROR(INDEX(_Lookup!$A$2:$A$500,MATCH(C25,_Lookup!$B$2:$B$500,0)),"")}
... D40: {=IFERROR(INDEX(_Lookup!$A$2:$A$500,MATCH(C40,_Lookup!$B$2:$B$500,0)),"")}
A42: 3. MEANINGS → groups[].meanings[]
A43: GroupKey | B43: MeaningOrder | C43: Content | D43: IsPublic
A44: 0 | B44: 0 | C44: Describes a past habit that no longer exists. | D44: TRUE
A45: 0 | B45: 0 | C45: There is a risk that / fear that something undesirable may happen. | D45: TRUE
A75: 4. EXAMPLES → groups[].meanings[].examples[] (nối qua GroupKey + MeaningOrder)
A76: GroupKey | B76: MeaningOrder | C76: Sentence | D76: Translation | E76: Note | F76: IsPublic
A77: 0 | B77: 0 | C77: I used to play football every weekend. | D77: Tôi từng chơi bóng đá mỗi cuối tuần. | F77: TRUE
A78: 0 | B78: 0 | C78: 台風が接近しているため、大雨になるおそれがあります。 | D78: As the typhoon approaches, there is a danger of heavy rain. | F78: TRUE
A79: 0 | B79: 0 | C79: この病気は感染するおそれがある。 | D79: There is a risk that this disease is contagious. | F79: TRUE
A118: 5. NOTES → notes[]
A119: GroupKey | B119: Content | C119: IsPublic
A120: 0 | B120: Not conjugated according to the subject; it is always followed by a verb infinitive (V-inf). | C120: TRUE
A121: 0 | B121: Formal expression used in news, weather forecasts, or official warnings to indicate a potential negative outcome. | C121: TRUE
A141: 6. FILTER IDS → filterIds[]
A142: FilterId (chọn) | B142: FilterId (giá trị)
A143: TOEIC
...

Sheet Grammar 7
A1: GRAMMAR TAB — 1 tab = 1 object JSON hoàn chỉnh (Grammar 1)
A3: 1. THÔNG TIN CHUNG → root: title / language / isPublic
A4: Field | B4: Value | C4: Ghi chú
A5: title | B5: ~に違いない (ni chigainai)
A6: language | B6: JA
A7: isPublic | B7: TRUE | C7: TRUE/FALSE
A9: 2. COMPONENTS → groups[].components[]
A10: GroupKey | B10: Order | C10: FormId (chọn) | D10: FormId (giá trị) | E10: Keyword | F10: Optional
A11: 0 | B11: 0 | C11: Động từ (Verb) | E11: used to | F11: TRUE
A12: 0 | B12: 0 | C12: N | D12: {=IFERROR(INDEX(_Lookup!$A$2:$A$500,MATCH(C12,_Lookup!$B$2:$B$500,0)),"")} | F12: TRUE
A13: 0 | B13: 1 | D13: {=IFERROR(INDEX(_Lookup!$A$2:$A$500,MATCH(C13,_Lookup!$B$2:$B$500,0)),"")} | E13: に違いない | F13: TRUE
D14: {=IFERROR(INDEX(_Lookup!$A$2:$A$500,MATCH(C14,_Lookup!$B$2:$B$500,0)),"")}
D15: {=IFERROR(INDEX(_Lookup!$A$2:$A$500,MATCH(C15,_Lookup!$B$2:$B$500,0)),"")}
D16: {=IFERROR(INDEX(_Lookup!$A$2:$A$500,MATCH(C16,_Lookup!$B$2:$B$500,0)),"")}
D17: {=IFERROR(INDEX(_Lookup!$A$2:$A$500,MATCH(C17,_Lookup!$B$2:$B$500,0)),"")}
D18: {=IFERROR(INDEX(_Lookup!$A$2:$A$500,MATCH(C18,_Lookup!$B$2:$B$500,0)),"")}
D19: {=IFERROR(INDEX(_Lookup!$A$2:$A$500,MATCH(C19,_Lookup!$B$2:$B$500,0)),"")}
D20: {=IFERROR(INDEX(_Lookup!$A$2:$A$500,MATCH(C20,_Lookup!$B$2:$B$500,0)),"")}
D21: {=IFERROR(INDEX(_Lookup!$A$2:$A$500,MATCH(C21,_Lookup!$B$2:$B$500,0)),"")}
D22: {=IFERROR(INDEX(_Lookup!$A$2:$A$500,MATCH(C22,_Lookup!$B$2:$B$500,0)),"")}
D23: {=IFERROR(INDEX(_Lookup!$A$2:$A$500,MATCH(C23,_Lookup!$B$2:$B$500,0)),"")}
D24: {=IFERROR(INDEX(_Lookup!$A$2:$A$500,MATCH(C24,_Lookup!$B$2:$B$500,0)),"")}
D25: {=IFERROR(INDEX(_Lookup!$A$2:$A$500,MATCH(C25,_Lookup!$B$2:$B$500,0)),"")}
... D40: {=IFERROR(INDEX(_Lookup!$A$2:$A$500,MATCH(C40,_Lookup!$B$2:$B$500,0)),"")}
A42: 3. MEANINGS → groups[].meanings[]
A43: GroupKey | B43: MeaningOrder | C43: Content | D43: IsPublic
A44: 0 | B44: 0 | C44: Describes a past habit that no longer exists. | D44: TRUE
A45: 0 | B45: 0 | C45: Must be / bound to be (strong conviction/certainty). | D45: TRUE
A75: 4. EXAMPLES → groups[].meanings[].examples[] (nối qua GroupKey + MeaningOrder)
A76: GroupKey | B76: MeaningOrder | C76: Sentence | D76: Translation | E76: Note | F76: IsPublic
A77: 0 | B77: 0 | C77: I used to play football every weekend. | D77: Tôi từng chơi bóng đá mỗi cuối tuần. | F77: TRUE
A78: 0 | B78: 0 | C78: 彼が犯人に違いない。 | D78: He must be the culprit. | F78: TRUE
A79: 0 | B79: 0 | C79: 彼女はきっと合格するに違いない。 | D79: She is bound to pass. | F79: TRUE
A118: 5. NOTES → notes[]
A119: GroupKey | B119: Content | C119: IsPublic
A120: 0 | B120: Not conjugated according to the subject; it is always followed by a verb infinitive (V-inf). | C120: TRUE
A121: 0 | B121: Indicates strong subjective conviction based on evidence or intuition. | C121: TRUE
A141: 6. FILTER IDS → filterIds[]
A142: FilterId (chọn) | B142: FilterId (giá trị)
A143: TOEIC
...

Sheet Grammar 8
A1: GRAMMAR TAB — 1 tab = 1 object JSON hoàn chỉnh (Grammar 1)
A3: 1. THÔNG TIN CHUNG → root: title / language / isPublic
A4: Field | B4: Value | C4: Ghi chú
A5: title | B5: ~をめぐって (wo megutte)
A6: language | B6: JA
A7: isPublic | B7: TRUE | C7: TRUE/FALSE
A9: 2. COMPONENTS → groups[].components[]
A10: GroupKey | B10: Order | C10: FormId (chọn) | D10: FormId (giá trị) | E10: Keyword | F10: Optional
A11: 0 | B11: 0 | C11: Động từ (Verb) | E11: used to | F11: TRUE
A12: 0 | B12: 0 | C12: N | D12: {=IFERROR(INDEX(_Lookup!$A$2:$A$500,MATCH(C12,_Lookup!$B$2:$B$500,0)),"")} | F12: TRUE
A13: 0 | B13: 1 | D13: {=IFERROR(INDEX(_Lookup!$A$2:$A$500,MATCH(C13,_Lookup!$B$2:$B$500,0)),"")} | E13: をめぐって | F13: TRUE
D14: {=IFERROR(INDEX(_Lookup!$A$2:$A$500,MATCH(C14,_Lookup!$B$2:$B$500,0)),"")}
D15: {=IFERROR(INDEX(_Lookup!$A$2:$A$500,MATCH(C15,_Lookup!$B$2:$B$500,0)),"")}
D16: {=IFERROR(INDEX(_Lookup!$A$2:$A$500,MATCH(C16,_Lookup!$B$2:$B$500,0)),"")}
D17: {=IFERROR(INDEX(_Lookup!$A$2:$A$500,MATCH(C17,_Lookup!$B$2:$B$500,0)),"")}
D18: {=IFERROR(INDEX(_Lookup!$A$2:$A$500,MATCH(C18,_Lookup!$B$2:$B$500,0)),"")}
D19: {=IFERROR(INDEX(_Lookup!$A$2:$A$500,MATCH(C19,_Lookup!$B$2:$B$500,0)),"")}
D20: {=IFERROR(INDEX(_Lookup!$A$2:$A$500,MATCH(C20,_Lookup!$B$2:$B$500,0)),"")}
D21: {=IFERROR(INDEX(_Lookup!$A$2:$A$500,MATCH(C21,_Lookup!$B$2:$B$500,0)),"")}
D22: {=IFERROR(INDEX(_Lookup!$A$2:$A$500,MATCH(C22,_Lookup!$B$2:$B$500,0)),"")}
D23: {=IFERROR(INDEX(_Lookup!$A$2:$A$500,MATCH(C23,_Lookup!$B$2:$B$500,0)),"")}
D24: {=IFERROR(INDEX(_Lookup!$A$2:$A$500,MATCH(C24,_Lookup!$B$2:$B$500,0)),"")}
D25: {=IFERROR(INDEX(_Lookup!$A$2:$A$500,MATCH(C25,_Lookup!$B$2:$B$500,0)),"")}
... D40: {=IFERROR(INDEX(_Lookup!$A$2:$A$500,MATCH(C40,_Lookup!$B$2:$B$500,0)),"")}
A42: 3. MEANINGS → groups[].meanings[]
A43: GroupKey | B43: MeaningOrder | C43: Content | D43: IsPublic
A44: 0 | B44: 0 | C44: Describes a past habit that no longer exists. | D44: TRUE
A45: 0 | B45: 0 | C45: Concerning / surrounding / over a controversial issue or topic. | D45: TRUE
A75: 4. EXAMPLES → groups[].meanings[].examples[] (nối qua GroupKey + MeaningOrder)
A76: GroupKey | B76: MeaningOrder | C76: Sentence | D76: Translation | E76: Note | F76: IsPublic
A77: 0 | B77: 0 | C77: I used to play football every weekend. | D77: Tôi từng chơi bóng đá mỗi cuối tuần. | F77: TRUE
A78: 0 | B78: 0 | C78: 新しい政策をめぐって、活発な議論が行われた。 | D78: A lively debate took place concerning the new policy. | F78: TRUE
A79: 0 | B79: 0 | C79: 遺産の相続をめぐって、親族間で争いが起きた。 | D79: A dispute arose among relatives over the inheritance. | F79: TRUE
A118: 5. NOTES → notes[]
A119: GroupKey | B119: Content | C119: IsPublic
A120: 0 | B120: Not conjugated according to the subject; it is always followed by a verb infinitive (V-inf). | C120: TRUE
A121: 0 | B121: Used when multiple parties argue, compete, or hold differing opinions regarding a central issue. | C121: TRUE
A141: 6. FILTER IDS → filterIds[]
A142: FilterId (chọn) | B142: FilterId (giá trị)
A143: TOEIC
...

Sheet Grammar 9
A1: GRAMMAR TAB — 1 tab = 1 object JSON hoàn chỉnh (Grammar 1)
A3: 1. THÔNG TIN CHUNG → root: title / language / isPublic
A4: Field | B4: Value | C4: Ghi chú
A5: title | B5: ~に過ぎない (ni suginai)
A6: language | B6: JA
A7: isPublic | B7: TRUE | C7: TRUE/FALSE
A9: 2. COMPONENTS → groups[].components[]
A10: GroupKey | B10: Order | C10: FormId (chọn) | D10: FormId (giá trị) | E10: Keyword | F10: Optional
A11: 0 | B11: 0 | C11: Động từ (Verb) | E11: used to | F11: TRUE
A12: 0 | B12: 0 | C12: N | D12: {=IFERROR(INDEX(_Lookup!$A$2:$A$500,MATCH(C12,_Lookup!$B$2:$B$500,0)),"")} | F12: TRUE
A13: 0 | B13: 1 | D13: {=IFERROR(INDEX(_Lookup!$A$2:$A$500,MATCH(C13,_Lookup!$B$2:$B$500,0)),"")} | E13: に過ぎない | F13: TRUE
D14: {=IFERROR(INDEX(_Lookup!$A$2:$A$500,MATCH(C14,_Lookup!$B$2:$B$500,0)),"")}
D15: {=IFERROR(INDEX(_Lookup!$A$2:$A$500,MATCH(C15,_Lookup!$B$2:$B$500,0)),"")}
D16: {=IFERROR(INDEX(_Lookup!$A$2:$A$500,MATCH(C16,_Lookup!$B$2:$B$500,0)),"")}
D17: {=IFERROR(INDEX(_Lookup!$A$2:$A$500,MATCH(C17,_Lookup!$B$2:$B$500,0)),"")}
D18: {=IFERROR(INDEX(_Lookup!$A$2:$A$500,MATCH(C18,_Lookup!$B$2:$B$500,0)),"")}
D19: {=IFERROR(INDEX(_Lookup!$A$2:$A$500,MATCH(C19,_Lookup!$B$2:$B$500,0)),"")}
D20: {=IFERROR(INDEX(_Lookup!$A$2:$A$500,MATCH(C20,_Lookup!$B$2:$B$500,0)),"")}
D21: {=IFERROR(INDEX(_Lookup!$A$2:$A$500,MATCH(C21,_Lookup!$B$2:$B$500,0)),"")}
D22: {=IFERROR(INDEX(_Lookup!$A$2:$A$500,MATCH(C22,_Lookup!$B$2:$B$500,0)),"")}
D23: {=IFERROR(INDEX(_Lookup!$A$2:$A$500,MATCH(C23,_Lookup!$B$2:$B$500,0)),"")}
D24: {=IFERROR(INDEX(_Lookup!$A$2:$A$500,MATCH(C24,_Lookup!$B$2:$B$500,0)),"")}
D25: {=IFERROR(INDEX(_Lookup!$A$2:$A$500,MATCH(C25,_Lookup!$B$2:$B$500,0)),"")}
... D40: {=IFERROR(INDEX(_Lookup!$A$2:$A$500,MATCH(C40,_Lookup!$B$2:$B$500,0)),"")}
A42: 3. MEANINGS → groups[].meanings[]
A43: GroupKey | B43: MeaningOrder | C43: Content | D43: IsPublic
A44: 0 | B44: 0 | C44: Describes a past habit that no longer exists. | D44: TRUE
A45: 0 | B45: 0 | C45: Nothing more than / merely / only. | D45: TRUE
A75: 4. EXAMPLES → groups[].meanings[].examples[] (nối qua GroupKey + MeaningOrder)
A76: GroupKey | B76: MeaningOrder | C76: Sentence | D76: Translation | E76: Note | F76: IsPublic
A77: 0 | B77: 0 | C77: I used to play football every weekend. | D77: Tôi từng chơi bóng đá mỗi cuối tuần. | F77: TRUE
A78: 0 | B78: 0 | C78: それは単なる噂に過ぎない。 | D78: That is nothing more than a rumor. | F78: TRUE
A79: 0 | B79: 0 | C79: 私は自分の義務を果たしたに過ぎません。 | D79: I was merely doing my duty. | F79: TRUE
A118: 5. NOTES → notes[]
A119: GroupKey | B119: Content | C119: IsPublic
A120: 0 | B120: Not conjugated according to the subject; it is always followed by a verb infinitive (V-inf). | C120: TRUE
A121: 0 | B121: Used to downplay or limit the importance or severity of something. | C121: TRUE
A141: 6. FILTER IDS → filterIds[]
A142: FilterId (chọn) | B142: FilterId (giá trị)
A143: TOEIC
...

Sheet Grammar 10
A1: GRAMMAR TAB — 1 tab = 1 object JSON hoàn chỉnh (Grammar 1)
A3: 1. THÔNG TIN CHUNG → root: title / language / isPublic
A4: Field | B4: Value | C4: Ghi chú
A5: title | B5: ~ざるを得ない (zaru wo e nai)
A6: language | B6: JA
A7: isPublic | B7: TRUE | C7: TRUE/FALSE
A9: 2. COMPONENTS → groups[].components[]
A10: GroupKey | B10: Order | C10: FormId (chọn) | D10: FormId (giá trị) | E10: Keyword | F10: Optional
A11: 0 | B11: 0 | C11: Động từ (Verb) | E11: used to | F11: TRUE
A12: 0 | B12: 0 | C12: V-ない | D12: {=IFERROR(INDEX(_Lookup!$A$2:$A$500,MATCH(C12,_Lookup!$B$2:$B$500,0)),"")} | F12: TRUE
A13: 0 | B13: 1 | D13: {=IFERROR(INDEX(_Lookup!$A$2:$A$500,MATCH(C13,_Lookup!$B$2:$B$500,0)),"")} | E13: ざるを得ない | F13: TRUE
D14: {=IFERROR(INDEX(_Lookup!$A$2:$A$500,MATCH(C14,_Lookup!$B$2:$B$500,0)),"")}
D15: {=IFERROR(INDEX(_Lookup!$A$2:$A$500,MATCH(C15,_Lookup!$B$2:$B$500,0)),"")}
D16: {=IFERROR(INDEX(_Lookup!$A$2:$A$500,MATCH(C16,_Lookup!$B$2:$B$500,0)),"")}
D17: {=IFERROR(INDEX(_Lookup!$A$2:$A$500,MATCH(C17,_Lookup!$B$2:$B$500,0)),"")}
D18: {=IFERROR(INDEX(_Lookup!$A$2:$A$500,MATCH(C18,_Lookup!$B$2:$B$500,0)),"")}
D19: {=IFERROR(INDEX(_Lookup!$A$2:$A$500,MATCH(C19,_Lookup!$B$2:$B$500,0)),"")}
D20: {=IFERROR(INDEX(_Lookup!$A$2:$A$500,MATCH(C20,_Lookup!$B$2:$B$500,0)),"")}
D21: {=IFERROR(INDEX(_Lookup!$A$2:$A$500,MATCH(C21,_Lookup!$B$2:$B$500,0)),"")}
D22: {=IFERROR(INDEX(_Lookup!$A$2:$A$500,MATCH(C22,_Lookup!$B$2:$B$500,0)),"")}
D23: {=IFERROR(INDEX(_Lookup!$A$2:$A$500,MATCH(C23,_Lookup!$B$2:$B$500,0)),"")}
D24: {=IFERROR(INDEX(_Lookup!$A$2:$A$500,MATCH(C24,_Lookup!$B$2:$B$500,0)),"")}
D25: {=IFERROR(INDEX(_Lookup!$A$2:$A$500,MATCH(C25,_Lookup!$B$2:$B$500,0)),"")}
... D40: {=IFERROR(INDEX(_Lookup!$A$2:$A$500,MATCH(C40,_Lookup!$B$2:$B$500,0)),"")}
A42: 3. MEANINGS → groups[].meanings[]
A43: GroupKey | B43: MeaningOrder | C43: Content | D43: IsPublic
A44: 0 | B44: 0 | C44: Describes a past habit that no longer exists. | D44: TRUE
A45: 0 | B45: 0 | C45: Have no choice but to / cannot help doing. | D45: TRUE
A75: 4. EXAMPLES → groups[].meanings[].examples[] (nối qua GroupKey + MeaningOrder)
A76: GroupKey | B76: MeaningOrder | C76: Sentence | D76: Translation | E76: Note | F76: IsPublic
A77: 0 | B77: 0 | C77: I used to play football every weekend. | D77: Tôi từng chơi bóng đá mỗi cuối tuần. | F77: TRUE
A78: 0 | B78: 0 | C78: 理由がどうであれ、ルール違反は処罰せざるを得ない。 | D78: Regardless of the reason, we have no choice but to punish rule violations. | F78: TRUE
A79: 0 | B79: 0 | C79: 悪天候のため、計画を変更せざるを得なかった。 | D79: Due to bad weather, we had no choice but to change the plan. | F79: TRUE
A118: 5. NOTES → notes[]
A119: GroupKey | B119: Content | C119: IsPublic
A120: 0 | B120: Not conjugated according to the subject; it is always followed by a verb infinitive (V-inf). | C120: TRUE
A121: 0 | B121: Formal written expression indicating that circumstances force an action against one's preference. | C121: TRUE
A141: 6. FILTER IDS → filterIds[]
A142: FilterId (chọn) | B142: FilterId (giá trị)
A143: TOEIC
...
